---
title: 为什么foreach里面为什么不能放promise
createTime: 2025/08/29 14:25:06
permalink: /home/048s519p/
---
**为什么foreach里面为什么不能放promise？**
---

### 1. forEach 是一个同步任务，它不支持处理异步函数

*   **`forEach` 的工作机制**：`forEach` 的本质是一个同步的迭代循环。它对数组中的每个元素，**同步地、立即地**执行一次提供的回调函数。它不会等待任何操作完成，它只负责“触发”或“调用”。
*   **事件循环（Event Loop）与回调队列**：JavaScript 有一个基于事件循环的并发模型。异步操作（如 `setTimeout`, `fetch`, `Promise.then`）会被放入“任务队列”或“微任务队列”中，等待当前**调用栈**（正在执行的同步代码）清空后，才会被事件循环取出来执行。
*   **问题所在**：
    1.  当 `forEach` 循环到一个元素时，它同步地调用了回调函数。
    2.  在回调函数内部，你创建了一个 `Promise`（一个异步操作）。这个 `Promise` 不会立即 resolve，它的 `.then()` 或 `await` 后面的代码会被推迟执行，放入微任务队列。
    3.  `forEach` 完全不管回调函数内部发生了什么异步操作。它不会等待这个 `Promise` 解决（resolve），而是立刻继续同步地迭代下一个元素，调用下一个回调函数。
    4.  因此，所有的异步操作几乎在同一时间被“启动”或“触发”，但它们的结果（`resolve` 或 `reject`）要等到整个 `forEach` 循环**结束后**（即同步代码全部执行完毕），事件循环才会去处理。

这就像你让一个报数员（`forEach`）去通知一排士兵（数组元素）开始跑步（异步任务）。报数员会以极快的速度对着每个士兵喊一声“跑！”，然后他的工作就结束了。所有士兵几乎同时开始跑，但谁先跑完、谁后跑完，报数员根本不关心，他也无法汇报最终的跑步结果。你得到的结果是“所有任务都已启动”，但**无法知晓它们何时完成，也无法保证其完成顺序**。

**代码示例：**
```javascript
const urls = ['url1', 'url2', 'url3'];
const results = [];

urls.forEach(async (url) => {
  // 这是一个异步函数，会返回一个 Promise
  const data = await fetch(url); // fetch 是异步的
  results.push(data);
});

// 这行代码会在 forEach 启动完所有 fetch 请求后立即执行
// 但此时所有 fetch 请求都还在进行中，results 是空的
console.log('Fetching finished?', results); // 输出： Fetching finished? []
```

---

### 2. 无法捕获异步函数中的错误

**详细说明：**

*   **同步错误的捕获**：传统的 `try...catch` 语句是同步的。它能捕获到在 `try` 块中**同步执行**的代码抛出的错误。
*   **异步错误的逃离**：在 `forEach` 的回调函数中，如果使用 `async/await` 或 `.then()`，错误是在异步操作完成时（即在未来的某个事件循环 tick 中）抛出的。此时，外层的 `try...catch` 块的执行上下文已经结束，它已经无法捕获到那个未来才发生的错误了。
*   **问题所在**：错误会“逃离” `try...catch`，导致成为未处理的 Promise 拒绝（Unhandled Promise rejection），可能会使程序崩溃。

**代码示例：**
```javascript
try {
  [1, 2, 3].forEach(async (num) => {
    if (num === 2) {
      throw new Error('Oops on 2'); // 这是一个在异步上下文中抛出的错误
    }
    console.log(num);
  });
} catch (error) {
  // 这里的 catch 块永远捕获不到上面抛出的异步错误
  console.error('Caught an error:', error);
}
// 输出: 1, 3
// 然后程序会报错：Uncaught (in promise) Error: Oops on 2
```

使用 `for...of` 循环配合 `await` 可以正确捕获错误，因为 `await` 会暂停循环，使得错误能在同步的 `try...catch` 上下文中抛出。

---

### 3. this 指向问题

**详细说明：**

*   **`forEach` 的参数设计**：`forEach` 方法的第二个参数允许你显式地指定回调函数内部的 `this` 值。`arr.forEach(callback, thisArg)`。
*   **箭头函数的特殊性**：箭头函数没有自己的 `this` 绑定，它会捕获其所在上下文的 `this` 值。如果你在 `forEach` 中使用了箭头函数，那么第二个参数 `thisArg` 会被忽略。
*   **问题所在**：
    *   如果你在 `forEach` 中使用了**普通函数**，并且希望函数内部的 `this` 指向某个对象，你必须使用第二个参数 `thisArg` 或者事先使用 `.bind()` 方法。否则，在非严格模式下 `this` 会指向全局对象（如 `window`），在严格模式下会是 `undefined`。这是一个常见的困惑点，虽然不直接与 `Promise` 相关，但在处理异步逻辑时如果涉及到 `this`，会加剧问题的复杂性。
    *   如果你使用了**异步箭头函数**，`this` 会正确指向定义它的外部上下文的 `this`，但这也意味着你无法通过 `forEach` 的第二个参数来动态改变它。

**代码示例（普通函数的问题）：**
```javascript
class MyClass {
  constructor() {
    this.values = [1, 2, 3];
    this.result = 0;
  }

  calculate() {
    this.values.forEach(function(num) {
      // 这个普通函数有自己的 this 上下文
      // 这里的 this 不再是 MyClass 的实例，除非使用 bind 或 thisArg
      this.result += num; // TypeError: Cannot read property 'result' of undefined
    });
    // 正确的做法是：
    // this.values.forEach(function(num) { ... }, this); // 传入 thisArg
    // 或者使用箭头函数：
    // this.values.forEach((num) => { this.result += num; });
  }
}

const myInstance = new MyClass();
myInstance.calculate();
```

正是因为 `forEach` 对异步操作的这些固有缺陷，在现代 JavaScript 开发中，**应避免在需要处理异步迭代时使用 `forEach`**。

**推荐使用以下方法替代：**

1.  **`for...of` 循环 + `await`**：
    *   这是处理异步迭代最清晰、最直接的方式。
    *   它是顺序执行的（一个完成后才进行下一个），保证了执行顺序。
    *   可以使用熟悉的 `try...catch` 正确捕获错误。
    ```javascript
    for (const url of urls) {
      try {
        const data = await fetch(url);
        results.push(data);
      } catch (error) {
        console.error(`Failed to fetch ${url}:`, error);
      }
    }
    console.log('All done!', results);
    ```

2.  **`Promise.all` + `map`**：
    *   如果你希望所有异步操作**并行执行**，并且等待所有结果，这是最佳选择。
    *   它比顺序执行的 `for...of` 循环效率更高。
    *   如果其中任何一个 Promise 被拒绝，整个 `Promise.all` 会立即拒绝（但可以通过 `Promise.allSettled` 来等待所有 Promise 完成，无论成功或失败）。
    ```javascript
    const promises = urls.map(url => fetch(url)); // map 只负责创建Promise数组，不执行
    try {
      const results = await Promise.all(promises); // 并行执行并等待所有结果
      console.log('All done!', results);
    } catch (error) {
      // 捕获第一个发生的错误
      console.error('One of the requests failed:', error);
    }
    ```